

* JavaScript에는 코드 실행 중에 예기치 못한 에러가 발생했을 때, 이로부터 코드의 실행 흐름을 복구할 수 있는 기능이 내장되어 있습니다. 이런 기능을 일러 예외 처리(exception handling)라고 합니다.( 와이파이가 갑자기 끊기는 경우등)


* try 블록 내부에 작성하면, 에러가 발생했을 때 코드의 실행 흐름이 try 블록에서 catch 블록으로 옮겨갑니다. 이 때, catch 블록 안에서는 에러에 대한 정보를 담고 있는 객체(위 코드의 e)를 사용할 수 있습니다.
```js
try {
  console.log('에러가 나기 직전까지의 코드는 잘 실행됩니다.');
  new Array(-1); // RangeError: Invalid array length
  console.log('에러가 난 이후의 코드는 실행되지 않습니다.');
} catch (e) {
  console.log('코드의 실행 흐름이 catch 블록으로 옮겨집니다.');
  alert(`다음과 같은 에러가 발생했습니다: ${e.name}: ${e.message}`);
}
```

* try 블록은 예외 처리를 위해서만 쓰이는 것은 아닙니다. try 블록 바로 뒤에 finally 블록이 오면, finally 블록에 있는 코드는 try 블록 안에서의 에러 발생 여부와 관계 없이 무조건 실행됩니다. 심지어 try 블록 내에서 return, break, continue 등으로 인해 코드의 실행 흐름이 즉시 이동될 때에도 마찬가지입니다.

```js
for (let i of [1, 2, 3]) {
  try {
    if (i === 3) {
      break;
    }
  } finally {
    console.log(`현재 i의 값: ${i}`);
  }
}
```

* finally 블록은 catch 블록과도 같이 사용됩니다. 이 때 코드의 실행 순서를 정리해 보면 다음과 같습니다
에러가 안 났을 때: try - finally
에러가 났을 때: try - 에러 발생 - catch - finally

```js
try {
  console.log('try');
  new Array(-1); // RangeError: Invalid array length
} catch (e) {
  console.log('catch');
} finally {
  console.log('finally');
}
```

* 순수함수(PUREfUNCTION): 숫자값처럼 절대값이 있는경우
모든 React 컴포넌트는 props에 대해서는 순수 함수처럼 동작해야합니다.

* 라이플 사이클 훅 
어떤 컴포넌트가 설정시 MOUNT, 삭제시 UNMOUNT

* 다음상태를 이전상태에서 계산하고 싶다면 함수를 만들어줘야함
```js
this.setState((prevState, props) => ({
  counter: prevState.counter + props.increment
}));
```
* 리액트에선 비동기함수를 이벤트리스너에 그냥 등록시키는 경우는 위험!




